<?xml version="1.0" encoding="utf-8"?>
<!-- This URDF was automatically created by SolidWorks to URDF Exporter! Originally created by Stephen Brawner (brawner@gmail.com) 
     Commit Version: 1.6.0-4-g7f85cfe  Build Version: 1.6.7995.38578
     For more information, please see http://wiki.ros.org/sw_urdf_exporter -->
<robot
  name="Horst900_Attemp2">
  <link
    name="base_link">
    <inertial>
      <origin
        xyz="-1.1001E-06 -2.599E-08 0.0058759"
        rpy="0 0 0" />
      <mass
        value="1.21" />
      <inertia
        ixx="0.011177"
        ixy="-7.4313E-08"
        ixz="-1.2107E-13"
        iyy="0.011689"
        iyz="-8.7273E-11"
        izz="0.022837" />
    </inertial>
    <visual>
      <origin
        xyz="0 0 0"
        rpy="0 0 0" />
      <geometry>
        <mesh
          filename="package://Horst900_Attemp2/meshes/base_link.STL" />
      </geometry>
      <material
        name="">
        <color
          rgba="0.89804 0.91765 0.92941 1" />
      </material>
    </visual>
    <collision>
      <origin
        xyz="0 0 0"
        rpy="0 0 0" />
      <geometry>
        <mesh
          filename="package://Horst900_Attemp2/meshes/base_link.STL" />
      </geometry>
    </collision>
  </link>
  <link
    name="link1">
    <inertial>
      <origin
        xyz="0.0007028 0.15394 -0.0031395"
        rpy="0 0 0" />
      <mass
        value="0.06735" />
      <inertia
        ixx="1.3452E-05"
        ixy="2.57E-10"
        ixz="6.9854E-22"
        iyy="2.558E-05"
        iyz="8.8646E-22"
        izz="1.3706E-05" />
    </inertial>
    <visual>
      <origin
        xyz="0 0 0"
        rpy="0 0 0" />
      <geometry>
        <mesh
          filename="package://Horst900_Attemp2/meshes/link1.STL" />
      </geometry>
      <material
        name="">
        <color
          rgba="0.89804 0.91765 0.92941 1" />
      </material>
    </visual>
    <collision>
      <origin
        xyz="0 0 0"
        rpy="0 0 0" />
      <geometry>
        <mesh
          filename="package://Horst900_Attemp2/meshes/link1.STL" />
      </geometry>
    </collision>
  </link>
  <joint
    name="joint1"
    type="revolute">
    <origin
      xyz="0 0 0.0565"
      rpy="1.5708 0 0" />
    <parent
      link="base_link" />
    <child
      link="link1" />
    <axis
      xyz="0 -1 0" />
    <limit
      lower="-3"
      upper="3"
      effort="0"
      velocity="0" />
  </joint>
  <link
    name="link2">
    <inertial>
      <origin
        xyz="-0.029492 -0.0027479 2.4951E-05"
        rpy="0 0 0" />
      <mass
        value="0.22367" />
      <inertia
        ixx="0.00056209"
        ixy="-0.00045945"
        ixz="-7.5228E-12"
        iyy="0.00056962"
        iyz="-1.4504E-11"
        izz="0.0011293" />
    </inertial>
    <visual>
      <origin
        xyz="0 0 0"
        rpy="0 0 0" />
      <geometry>
        <mesh
          filename="package://Horst900_Attemp2/meshes/link2.STL" />
      </geometry>
      <material
        name="">
        <color
          rgba="0.25098 0.25098 0.25098 1" />
      </material>
    </visual>
    <collision>
      <origin
        xyz="0 0 0"
        rpy="0 0 0" />
      <geometry>
        <mesh
          filename="package://Horst900_Attemp2/meshes/link2.STL" />
      </geometry>
    </collision>
  </link>
  <joint
    name="joint2"
    type="revolute">
    <origin
      xyz="0.05675 0.28257 0"
      rpy="0 0 0" />
    <parent
      link="link1" />
    <child
      link="link2" />
    <axis
      xyz="0 0 1" />
    <limit
      lower="-3"
      upper="3"
      effort="0"
      velocity="0" />
  </joint>
  <link
    name="link3">
    <inertial>
      <origin
        xyz="-2.4854E-05 0.036079 -0.015293"
        rpy="0 0 0" />
      <mass
        value="0.25309" />
      <inertia
        ixx="0.00057293"
        ixy="-1.7292E-10"
        ixz="-6.921E-10"
        iyy="0.00051593"
        iyz="-1.8197E-05"
        izz="8.4556E-05" />
    </inertial>
    <visual>
      <origin
        xyz="0 0 0"
        rpy="0 0 0" />
      <geometry>
        <mesh
          filename="package://Horst900_Attemp2/meshes/link3.STL" />
      </geometry>
      <material
        name="">
        <color
          rgba="0 0.54902 0.70588 1" />
      </material>
    </visual>
    <collision>
      <origin
        xyz="0 0 0"
        rpy="0 0 0" />
      <geometry>
        <mesh
          filename="package://Horst900_Attemp2/meshes/link3.STL" />
      </geometry>
    </collision>
  </link>
  <joint
    name="joint3"
    type="revolute">
    <origin
      xyz="6.7742E-05 0.407 0"
      rpy="0 1.5708 0" />
    <parent
      link="link2" />
    <child
      link="link3" />
    <axis
      xyz="1 0 0" />
    <limit
      lower="-3"
      upper="3"
      effort="0"
      velocity="0" />
  </joint>
  <link
    name="link4">
    <inertial>
      <origin
        xyz="-0.19659 -0.0035332 3.5047E-05"
        rpy="0 0 0" />
      <mass
        value="0.038503" />
      <inertia
        ixx="6.2907E-05"
        ixy="-2.0171E-05"
        ixz="-3.1267E-08"
        iyy="0.00024462"
        iyz="-7.0774E-09"
        izz="0.00022597" />
    </inertial>
    <visual>
      <origin
        xyz="0 0 0"
        rpy="0 0 0" />
      <geometry>
        <mesh
          filename="package://Horst900_Attemp2/meshes/link4.STL" />
      </geometry>
      <material
        name="">
        <color
          rgba="0.25098 0.25098 0.25098 1" />
      </material>
    </visual>
    <collision>
      <origin
        xyz="0 0 0"
        rpy="0 0 0" />
      <geometry>
        <mesh
          filename="package://Horst900_Attemp2/meshes/link4.STL" />
      </geometry>
    </collision>
  </link>
  <joint
    name="joint4"
    type="revolute">
    <origin
      xyz="-2.4956E-05 0.03648 0.12703"
      rpy="0 1.5708 0" />
    <parent
      link="link3" />
    <child
      link="link4" />
    <axis
      xyz="1 0 0" />
    <limit
      lower="-3"
      upper="3"
      effort="0"
      velocity="0" />
  </joint>
  <link
    name="link5">
    <inertial>
      <origin
        xyz="-0.014949 -0.00019999 -0.024498"
        rpy="0 0 0" />
      <mass
        value="0.025507" />
      <inertia
        ixx="2.1268E-05"
        ixy="1.4476E-11"
        ixz="-2.7343E-07"
        iyy="1.9292E-05"
        iyz="4.8717E-11"
        izz="1.2407E-05" />
    </inertial>
    <visual>
      <origin
        xyz="0 0 0"
        rpy="0 0 0" />
      <geometry>
        <mesh
          filename="package://Horst900_Attemp2/meshes/link5.STL" />
      </geometry>
      <material
        name="">
        <color
          rgba="0.25098 0.25098 0.25098 1" />
      </material>
    </visual>
    <collision>
      <origin
        xyz="0 0 0"
        rpy="0 0 0" />
      <geometry>
        <mesh
          filename="package://Horst900_Attemp2/meshes/link5.STL" />
      </geometry>
    </collision>
  </link>
  <joint
    name="joint5"
    type="revolute">
    <origin
      xyz="-0.308 0 0"
      rpy="-1.5708 0 3.1416" />
    <parent
      link="link4" />
    <child
      link="link5" />
    <axis
      xyz="0 1 0" />
    <limit
      lower="-3"
      upper="3"
      effort="0"
      velocity="0" />
  </joint>
  <link
    name="link6">
    <inertial>
      <origin
        xyz="0.46804 -6.2595E-05 0.59277"
        rpy="0 0 0" />
      <mass
        value="1.8181" />
      <inertia
        ixx="0.17075"
        ixy="-3.9322E-07"
        ixz="-0.023792"
        iyy="0.18483"
        iyz="3.8068E-05"
        izz="0.038533" />
    </inertial>
    <visual>
      <origin
        xyz="0 0 0"
        rpy="0 0 0" />
      <geometry>
        <mesh
          filename="package://Horst900_Attemp2/meshes/link6.STL" />
      </geometry>
      <material
        name="">
        <color
          rgba="0.25098 0.25098 0.25098 1" />
      </material>
    </visual>
    <collision>
      <origin
        xyz="0 0 0"
        rpy="0 0 0" />
      <geometry>
        <mesh
          filename="package://Horst900_Attemp2/meshes/link6.STL" />
      </geometry>
    </collision>
  </link>
  <joint
    name="joint6"
    type="revolute">
    <origin
      xyz="0.0001 -0.0002 0"
      rpy="0 0 3.1416" />
    <parent
      link="link5" />
    <child
      link="link6" />
    <axis
      xyz="0 0 -1" />
    <limit
      lower="0"
      upper="0"
      effort="0"
      velocity="0" />
  </joint>
</robot>